Workbook
Name Enum_Availability: 'README'!$X$2:$X$6
Name Enum_Confidence: 'README'!$Y$2:$Y$5
Name Enum_VehicleStatus: 'README'!$Z$2:$Z$7
Name Enum_ConfigurationStatus: 'README'!$AA$2:$AA$5
Name Enum_RequirementType: 'README'!$AB$2:$AB$5
Name Enum_SourceType: 'README'!$AC$2:$AC$10
Name Enum_EvidenceType: 'README'!$AD$2:$AD$7
Name Enum_Market: 'README'!$AE$2:$AE$8
Name Enum_Unit: 'README'!$AF$2:$AF$13
Name Enum_FrameworkStatus: 'README'!$AG$2:$AG$5
Name Enum_DecisionStatus: 'README'!$AH$2:$AH$5
Name Validation_Boolean: 'README'!$AI$2:$AI$3

Sheet README
A1: Field | B1: Value | X1: Enum_Availability | Y1: Enum_Confidence | Z1: Enum_VehicleStatus | AA1: Enum_ConfigurationStatus | AB1: Enum_RequirementType | AC1: Enum_SourceType | AD1: Enum_EvidenceType | AE1: Enum_Market | AF1: Enum_Unit | AG1: Enum_FrameworkStatus | AH1: Enum_DecisionStatus | AI1: Validation_Boolean
A2: WorkbookVersion | B2: 1.3 | X2: STANDARD | Y2: HIGH | Z2: ANNOUNCED | AA2: AVAILABLE | AB2: HARD | AC2: MANUFACTURER | AD2: SPECIFICATION | AE2: NO | AF2: MM | AG2: DRAFT | AH2: PROPOSED | AI2: TRUE
A3: FrameworkVersion | B3: 1.4 | X3: OPTIONAL | Y3: MEDIUM | Z3: PREORDER | AA3: UPCOMING | AB3: WEIGHTED | AC3: GOVERNMENT | AD3: MEASUREMENT | AE3: SE | AF3: CM | AG3: REVIEW | AH3: ACCEPTED | AI3: FALSE
A4: LastUpdated | B4: 2026-07-06 | X4: PACKAGE | Y4: LOW | Z4: AVAILABLE | AA4: DISCONTINUED | AB4: INFORMATIONAL | AC4: CERTIFICATION | AD4: OBSERVATION | AE4: DK | AF4: M | AG4: LOCKED | AH4: IMPLEMENTED
A5: Domain | B5: Battery electric vehicle decision framework | X5: UNAVAILABLE | Y5: UNKNOWN | Z5: DISCONTINUED | AA5: UNKNOWN | AB5: EXCLUDED | AC5: PROFESSIONAL_REVIEW | AD5: TEST_RESULT | AE5: FI | AF5: KM | AG5: DEPRECATED | AH5: SUPERSEDED
A6: Purpose | B6: Reference implementation of the documented EV Decision Framework schema. | X6: UNKNOWN | Z6: CANCELLED | AC6: OWNER_REPORT | AD6: REVIEW_SUMMARY | AE6: EU | AF6: KMH
A7: Notes | B7: Scoring mechanics implemented per ADR-005: 10_Scoring RawScore/WeightedScore are now formulas (1-5 Review.Score scale, documented rounding rule); new 12_OverallScores worksheet aggregates Configuration-level Overall Score with mandatory CoveragePercent. | Z7: UNKNOWN | AC7: COMMUNITY | AD7: OWNER_EXPERIENCE | AE7: UK | AF7: KWH
A8: Status | B8: LOCKED | AC8: DATABASE | AE8: GLOBAL | AF8: KWH_100KM
AC9: VIDEO | AF9: KW
AC10: OTHER | AF10: NM
AF11: KG
AF12: L
AF13: DB

Sheet 01_Criteria
A1: CriterionID | B1: Category | C1: Name | D1: Description | E1: Type | F1: Weight | G1: HardRequirement | H1: Active | I1: Notes | J1: FrameworkVersion
A2: M001 | B2: Hard requirement | C2: Elbil | D2: Kun helelektriske biler vurderes. | E2: HARD | F2: 0 | G2: TRUE | H2: TRUE | J2: 1.0
A3: M002 | B3: Hard requirement | C3: Lengde ≤ 4500 mm | D3: Garasjekrav. Oppgitt total lengde må være 4500 mm eller lavere. | E3: HARD | F3: 0 | G3: TRUE | H3: TRUE | J3: 1.0
A4: M003 | B4: Hard requirement | C4: 300 km vinter motorvei | D4: Funksjonskrav: Oslo–Grimstad/E18 vinter uten praktisk rekkeviddebekymring. | E4: HARD | F4: 0 | G4: TRUE | H4: TRUE | J4: 1.0
A5: M004 | B5: Hard requirement | C5: Adaptiv cruisekontroll | D5: Rio mangler dette; sentralt for oppgradering. | E5: HARD | F5: 0 | G5: TRUE | H5: TRUE | J5: 1.0
A6: M005 | B6: Hard requirement | C6: Ryggekamera eller bedre | D6: Minimum parkeringskamera. 360-kamera scores i teknologi/utstyr. | E6: HARD | F6: 0 | G6: TRUE | H6: TRUE | J6: 1.0
A7: W001 | B7: Kjøreopplevelse | C7: Kupéstøy i motorveifart | D7: Vektlegger stille kupé tungt, særlig vinter/motorvei. | E7: WEIGHTED | F7: 8 | G7: FALSE | H7: TRUE | J7: 1.0
A8: W002 | B8: Kjøreopplevelse | C8: Komfort/fjæring/seter | D8: Komfort over sportslighet. | E8: WEIGHTED | F8: 7 | G8: FALSE | H8: TRUE | J8: 1.0
A9: W003 | B9: Kjøreopplevelse | C9: Sikt og manøvrering | D9: God sikt og enkel parkering i hverdagen. | E9: WEIGHTED | F9: 5 | G9: FALSE | H9: TRUE | J9: 1.0
A10: W004 | B10: Kjøreopplevelse | C10: Presis styring/kontrollfølelse | D10: Presis, trygg og forutsigbar styring, ikke rå sportslighet. | E10: WEIGHTED | F10: 5 | G10: FALSE | H10: TRUE | J10: 1.0
A11: W005 | B11: Teknologi | C11: Programvare/infotainment kvalitet | D11: Dersom programvare må betjenes, skal den føles bra. | E11: WEIGHTED | F11: 7 | G11: FALSE | H11: TRUE | J11: 1.0
A12: W006 | B12: Teknologi | C12: OTA/fremtidssikring | D12: Viktig for 8–10 års eierhorisont. | E12: WEIGHTED | F12: 4 | G12: FALSE | H12: TRUE | J12: 1.0
A13: W007 | B13: Teknologi | C13: Apple CarPlay/integrasjon | D13: CarPlay og mobilintegrasjon vektlegges. | E13: WEIGHTED | F13: 3 | G13: FALSE | H13: TRUE | J13: 1.0
... A30: I004 | B30: Ikke målt | C30: Wow-faktor / hype | D30: Skal ikke drive beslutningen. | E30: INFORMATIONAL | F30: 0 | G30: FALSE | H30: TRUE | J30: 1.0

Sheet 02_Vehicles
A1: VehicleID | B1: Manufacturer | C1: Model | D1: ModelYear | E1: Platform | F1: Status | G1: Notes
A2: KIA_EV2 | B2: Kia | C2: EV2 | D2: UNKNOWN | E2: UNKNOWN | F2: AVAILABLE | G2: Official dealer sales quote from Bertel O. Steen Lorenskog (authorized Kia dealer), quote valid to 2026-07-12, reviewed 2026-07-06 - supersedes the earlier "not listed on Kia Norway model list" observation with concrete, dated transactional evidence of market availability. Configuration: EV2 FWD Long Range GT Line, 135 hk, forhjulsdrift. No battery capacity, WLTP range, charging power, or dimensions were stated anywhere in the quote document.
A3: TESLA_MODEL_3 | B3: Tesla | C3: Model 3 | D3: UNKNOWN | E3: UNKNOWN | F3: AVAILABLE | G3: Tesla Norway Model 3 page reviewed 2026-07-06: https://www.tesla.com/no_no/model3; model year and platform not specified in workbook-supported source fields.
A4: RENAULT_4 | B4: Renault | C4: 4 E-Tech Electric | D4: UNKNOWN | E4: UNKNOWN | F4: AVAILABLE | G4: Renault Norway product page and official price list (Versjon 2, 01-06-2026) reviewed 2026-07-06: https://www.renault.no/personbil/renault-4-e-tech-electric. Model year not specified in workbook-supported source fields.
A5: SKODA_ELROQ | B5: Škoda | C5: Elroq | D5: UNKNOWN | E5: UNKNOWN | F5: AVAILABLE | G5: Skoda Norway product page and official 2027-model price list (29.06.2026) reviewed 2026-07-06: https://www.skoda-auto.no/modeller/elroq/elroq. Platform not specified in workbook-supported source fields. Length (4488mm) sourced from global technical data sheet (5.5.2025) - see SRC_SKODA_GLOBAL_TECHDATA notes on model-year cross-source discrepancy.
A6: VOLVO_EX30 | B6: Volvo | C6: EX30 | D6: UNKNOWN | E6: UNKNOWN | F6: AVAILABLE | G6: Volvo Norway official specifications page reviewed 2026-07-06: https://www.volvocars.com/no/cars/ex30-electric/specifications/. Model year and platform not specified in workbook-supported source fields.

Sheet 03_Configurations
A1: ConfigurationID | B1: VehicleID | C1: Market | D1: Status | E1: Trim | F1: BasePrice | G1: ConfiguredPrice | H1: Notes
A2: TESLA_MODEL_3_RWD | B2: TESLA_MODEL_3 | C2: NO | D2: AVAILABLE | E2: Bakhjulsdrift | H2: Tesla Norway Model 3 page reviewed 2026-07-06: https://www.tesla.com/no_no/model3; official price not exposed in accessible source content. Configuration Status recorded as AVAILABLE: trim is listed on the official Tesla Norway configurator as of the same review date (ADR-004 / IMPL-002).
A3: TESLA_MODEL_3_LONG_RANGE_AWD | B3: TESLA_MODEL_3 | C3: NO | D3: AVAILABLE | E3: Long Range firehjulsdrift | H3: Tesla Norway Model 3 page reviewed 2026-07-06: https://www.tesla.com/no_no/model3; official price not exposed in accessible source content. Configuration Status recorded as AVAILABLE: trim is listed on the official Tesla Norway configurator as of the same review date (ADR-004 / IMPL-002).
A4: TESLA_MODEL_3_LONG_RANGE_RWD | B4: TESLA_MODEL_3 | C4: NO | D4: AVAILABLE | E4: Long Range bakhjulsdrift | F4: 400539 | G4: 400539 | H4: Tesla Norway Model 3 page reviewed 2026-07-06: https://www.tesla.com/no_no/model3; official price not exposed in accessible source content. Configuration Status recorded as AVAILABLE: trim is listed on the official Tesla Norway configurator as of the same review date (ADR-004 / IMPL-002). M003 (winter highway range): Not verified. Two winter tests were found but both are unreliable matches: a 2022 test used a superseded pre-refresh Model 3 generation with a WLTP figure (614km) that matches no current trim, and a NAF winter 2025 test reports 702km WLTP (matching none of this workbook's four recorded Model 3 configurations) without specifying which trim was tested. Remains genuinely Unknown. Price verified 2026-07-06 via official Tesla Norway configurator (SRC_TESLA_NO_MODEL3_DESIGN): 400539 kr incl. VAT/fees, no optional extras selected (previously unpriced under DATA-001).
A5: TESLA_MODEL_3_PERFORMANCE | B5: TESLA_MODEL_3 | C5: NO | D5: AVAILABLE | E5: Performance | H5: Tesla Norway Model 3 page reviewed 2026-07-06: https://www.tesla.com/no_no/model3; official price not exposed in accessible source content. Configuration Status recorded as AVAILABLE: trim is listed on the official Tesla Norway configurator as of the same review date (ADR-004 / IMPL-002).
A6: RENAULT_4_EVOLUTION_URBAN | B6: RENAULT_4 | C6: NO | D6: AVAILABLE | E6: Evolution (Urban Range, 40 kWh) | F6: 299900 | G6: 299900 | H6: Renault Norway official price list (Versjon 2, 01-06-2026) reviewed 2026-07-06. Fails Hard Requirement M004 (Adaptive Cruise Control): Evolution trim has only fixed-speed Cruise Control, not adaptive - confirmed in the price list equipment comparison table. Not eligible for weighted scoring.
A7: RENAULT_4_EVOLUTION_COMFORT | B7: RENAULT_4 | C7: NO | D7: AVAILABLE | E7: Evolution (Comfort Range, 52 kWh) | F7: 327900 | G7: 327900 | H7: Renault Norway official price list (Versjon 2, 01-06-2026) reviewed 2026-07-06. Fails Hard Requirement M004 (Adaptive Cruise Control): Evolution trim has only fixed-speed Cruise Control, not adaptive - confirmed in the price list equipment comparison table. Not eligible for weighted scoring.
A8: RENAULT_4_TECHNO | B8: RENAULT_4 | C8: NO | D8: AVAILABLE | E8: Techno (Comfort Range, 52 kWh) | F8: 364900 | G8: 364900 | H8: Renault Norway official price list (Versjon 2, 01-06-2026) reviewed 2026-07-06. Meets all checked Hard Requirements (BEV, length 4140mm, Intelligent cruise control multi target = adaptive, standard rearview camera). M003 (winter highway range) remains Unknown - no winter test data reviewed. M003 (winter highway range): No dedicated deep-winter test found for this exact configuration. Closest available data point (elbil.no, Iconic trim - same 52kWh/150hk powertrain as Techno, but a different equipment level) measured 287 km at constant 100km/h highway driving in mild 5-7C conditions - NOT true winter cold. Since colder conditions would be expected to reduce range further, this data point is a concerning signal rather than a confident pass: the hard requirement remains genuinely uncertain, possibly at risk of failing, for this configuration. Flagged for the user's attention rather than resolved either way.
A9: RENAULT_4_TECHNO_PLEIN_SUD | B9: RENAULT_4 | C9: NO | D9: AVAILABLE | E9: Techno Plein Sud (Comfort Range, 52 kWh, canvas roof) | F9: 374900 | G9: 374900 | H9: Renault Norway official price list (Versjon 2, 01-06-2026) reviewed 2026-07-06. Shares Techno equipment level (adaptive cruise control, rearview camera); canvas soltak variant. M003 remains Unknown.
A10: RENAULT_4_ICONIC | B10: RENAULT_4 | C10: NO | D10: AVAILABLE | E10: Iconic (Comfort Range, 52 kWh) | F10: 389900 | G10: 389900 | H10: Renault Norway official price list (Versjon 2, 01-06-2026) reviewed 2026-07-06. Meets all checked Hard Requirements (BEV, length 4140mm, Intelligent cruise control multi target = adaptive, standard rearview camera). M003 remains Unknown.
A11: RENAULT_4_ICONIC_PLEIN_SUD | B11: RENAULT_4 | C11: NO | D11: AVAILABLE | E11: Iconic Plein Sud (Comfort Range, 52 kWh, canvas roof) | F11: 399900 | G11: 399900 | H11: Renault Norway official price list (Versjon 2, 01-06-2026) reviewed 2026-07-06. Shares Iconic equipment level (adaptive cruise control, rearview camera); canvas soltak variant. M003 remains Unknown.
A12: SKODA_ELROQ_ESSENCE_60 | B12: SKODA_ELROQ | C12: NO | D12: AVAILABLE | E12: Essence 60 (RWD, 58 kWh) | F12: 342900 | G12: 342900 | H12: Skoda Norway official price list (2027-modell, 29.06.2026) reviewed 2026-07-06. Meets all checked Hard Requirements: BEV, length 4488mm (only 12mm under the 4500mm limit - tight margin, flagged), Prediktiv adaptiv cruisekontroll standard, Ryggekamera standard. M003 (winter highway range) remains Unknown.
A13: SKODA_ELROQ_SELECTION_60 | B13: SKODA_ELROQ | C13: NO | D13: AVAILABLE | E13: Selection 60 (RWD, 58 kWh) | F13: 374900 | G13: 374900 | H13: Skoda Norway official price list (2027-modell, 29.06.2026) reviewed 2026-07-06. Reportedly the most popular Elroq variant per Skoda. Meets all checked Hard Requirements (see Essence 60 note; same length/ACC/camera). M003 remains Unknown. M003 (winter highway range): Not verified. NAF's El Prix winter 2026 test included only the Elroq RS variant (different chassis/suspension/power tier), and the results table was rendered as an image, not extractable as text. Searched but found no dedicated winter test for Selection 60 specifically. Remains genuinely Unknown, not assumed.
A14: SKODA_ELROQ_SELECTION_85X | B14: SKODA_ELROQ | C14: NO | D14: AVAILABLE | E14: Selection 85x (AWD, 77 kWh) | F14: 492900 | G14: 492900 | H14: Skoda Norway official price list (2027-modell, 29.06.2026) reviewed 2026-07-06. Meets all checked Hard Requirements (see Essence 60 note). M003 remains Unknown.
A15: SKODA_ELROQ_RS | B15: SKODA_ELROQ | C15: NO | D15: AVAILABLE | E15: RS (AWD, 77 kWh) | F15: 531900 | G15: 531900 | H15: Skoda Norway official price list (2027-modell, 29.06.2026) reviewed 2026-07-06. Meets all checked Hard Requirements (see Essence 60 note). M003 remains Unknown.
A16: VOLVO_EX30_P5 | B16: VOLVO_EX30 | C16: NO | D16: AVAILABLE | E16: P5 (RWD, 51 kWh) | F16: 349900 | G16: 349900 | H16: Volvo Norway official specifications page reviewed 2026-07-06. Meets checked Hard Requirements: BEV, length 4233mm (comfortable margin under 4500mm limit), adaptive cruise control confirmed present via Motor.no test of the P8 AWD (same driver-assistance suite across the range, though functionally criticized in winter conditions). Rearview camera standard equipment not independently confirmed via a precisely-sourced fetch - left Unknown rather than assumed. M003 (winter highway range) remains Unknown.
A17: VOLVO_EX30_P5_LONG_RANGE | B17: VOLVO_EX30 | C17: NO | D17: AVAILABLE | E17: P5 Long Range (RWD, 69 kWh) | F17: 437900 | G17: 437900 | H17: Volvo Norway official specifications page reviewed 2026-07-06. Same Hard Requirement notes as P5 (see above).
... A19: KIA_EV2_FWD_LONG_RANGE_GT_LINE | B19: KIA_EV2 | C19: NO | D19: AVAILABLE | E19: FWD Long Range GT Line, 135 hk | F19: 346417 | G19: 423340 | H19: Official Bertel O. Steen (Kia dealer) sales quote reviewed 2026-07-06, valid to 2026-07-12. BasePrice (346417 kr) = base EV2 FWD Long Range (251655 kr) + GT Line package (94762 kr), i.e. the trim as sold. ConfiguredPrice (423340 kr) = this specific quote total, which additionally includes buyer-selected options not part of the base GT Line trim: 4-seat sliding-seat conversion (+3200 kr), 16" Nokian studded winter wheels (+23603 kr), plus delivery (12500 kr), VAT (21430 kr) and registration tax/vrakpant (16190 kr). Colour (Frost Blue - Solid) and interior (Grey/Black) were no-cost selections. No battery capacity, WLTP range, charging power, or vehicle dimensions were stated in the source document - these remain Unknown pending a manufacturer specification sheet. M003 (winter highway range): Not verified. No independent winter test was found for the Kia EV2 - likely because the model is too new to the Norwegian market to have been included in a winter test cycle yet. Remains genuinely Unknown.

Sheet 04_Technical
A1: TechnicalID | B1: VehicleID | C1: ConfigurationID | D1: TechnicalField | E1: Value | F1: Unit | G1: SourceID | H1: Confidence | I1: LastUpdated | J1: FrameworkVersion
D2: Length | F2: MM | H2: UNKNOWN | J2: 1.0
D3: WLTP range | F3: KM | H3: UNKNOWN | J3: 1.0
D4: Winter highway range estimate | F4: KM | H4: UNKNOWN | J4: 1.0
D5: Battery net | F5: KWH | H5: UNKNOWN | J5: 1.0
D6: DC max charging | F6: KW | H6: UNKNOWN | J6: 1.0
D7: Boot volume | F7: L | H7: UNKNOWN | J7: 1.0
A8: TECH_000001 | B8: TESLA_MODEL_3 | D8: Length | E8: 4720 | F8: MM | G8: SRC_TESLA_NO_MODEL3_CONFIGURATOR | H8: MEDIUM | I8: 2026-07-06 | J8: 1.2
A9: TECH_000002 | B9: TESLA_MODEL_3 | D9: Width (mirrors unfolded) | E9: 2089 | F9: MM | G9: SRC_TESLA_NO_MODEL3_CONFIGURATOR | H9: MEDIUM | I9: 2026-07-06 | J9: 1.2
A10: TECH_000003 | B10: TESLA_MODEL_3 | D10: Boot volume | E10: 682 | F10: L | G10: SRC_TESLA_NO_MODEL3_CONFIGURATOR | H10: MEDIUM | I10: 2026-07-06 | J10: 1.2
A11: TECH_000004 | C11: TESLA_MODEL_3_RWD | D11: Height | E11: 1440 | F11: MM | G11: SRC_TESLA_NO_MODEL3_CONFIGURATOR | H11: MEDIUM | I11: 2026-07-06 | J11: 1.2
A12: TECH_000005 | C12: TESLA_MODEL_3_RWD | D12: Width (mirrors folded) | E12: 1850 | F12: MM | G12: SRC_TESLA_NO_MODEL3_CONFIGURATOR | H12: MEDIUM | I12: 2026-07-06 | J12: 1.2
A13: TECH_000006 | C13: TESLA_MODEL_3_RWD | D13: Ground clearance | E13: 138 | F13: MM | G13: SRC_TESLA_NO_MODEL3_CONFIGURATOR | H13: MEDIUM | I13: 2026-07-06 | J13: 1.2
A14: TECH_000007 | C14: TESLA_MODEL_3_RWD | D14: Kerb weight (MRO) | E14: 1847 | F14: KG | G14: SRC_TESLA_NO_MODEL3_CONFIGURATOR | H14: MEDIUM | I14: 2026-07-06 | J14: 1.2
A15: TECH_000008 | C15: TESLA_MODEL_3_RWD | D15: WLTP range | E15: 534 | F15: KM | G15: SRC_TESLA_NO_MODEL3_CONFIGURATOR | H15: MEDIUM | I15: 2026-07-06 | J15: 1.2
A16: TECH_000009 | C16: TESLA_MODEL_3_RWD | D16: WLTP consumption | E16: 13 | F16: KWH_100KM | G16: SRC_TESLA_NO_MODEL3_CONFIGURATOR | H16: MEDIUM | I16: 2026-07-06 | J16: 1.2
A17: TECH_000010 | C17: TESLA_MODEL_3_RWD | D17: DC max charging | E17: 175 | F17: KW | G17: SRC_TESLA_NO_MODEL3_CONFIGURATOR | H17: MEDIUM | I17: 2026-07-06 | J17: 1.2
A18: TECH_000011 | C18: TESLA_MODEL_3_LONG_RANGE_AWD | D18: Height | E18: 1441 | F18: MM | G18: SRC_TESLA_NO_MODEL3_CONFIGURATOR | H18: MEDIUM | I18: 2026-07-06 | J18: 1.2
A19: TECH_000012 | C19: TESLA_MODEL_3_LONG_RANGE_AWD | D19: Width (mirrors folded) | E19: 1933 | F19: MM | G19: SRC_TESLA_NO_MODEL3_CONFIGURATOR | H19: MEDIUM | I19: 2026-07-06 | J19: 1.2
A20: TECH_000013 | C20: TESLA_MODEL_3_LONG_RANGE_AWD | D20: Ground clearance | E20: 138 | F20: MM | G20: SRC_TESLA_NO_MODEL3_CONFIGURATOR | H20: MEDIUM | I20: 2026-07-06 | J20: 1.2
A21: TECH_000014 | C21: TESLA_MODEL_3_LONG_RANGE_AWD | D21: Kerb weight (MRO) | E21: 1899 | F21: KG | G21: SRC_TESLA_NO_MODEL3_CONFIGURATOR | H21: MEDIUM | I21: 2026-07-06 | J21: 1.2
A22: TECH_000015 | C22: TESLA_MODEL_3_LONG_RANGE_AWD | D22: WLTP range | E22: 660 | F22: KM | G22: SRC_TESLA_NO_MODEL3_CONFIGURATOR | H22: MEDIUM | I22: 2026-07-06 | J22: 1.2
... A40: TECH_000033 | C40: TESLA_MODEL_3_PERFORMANCE | D40: Top speed | E40: 262 | F40: KMH | G40: SRC_TESLA_NO_MODEL3_CONFIGURATOR | H40: MEDIUM | I40: 2026-07-06 | J40: 1.2
A41: TECH_000034 | B41: RENAULT_4 | D41: Length | E41: 4140 | F41: MM | G41: SRC_RENAULT_NO_R4_PAGE | H41: MEDIUM | I41: 2026-07-06 | J41: 1.4
A42: TECH_000035 | B42: RENAULT_4 | D42: Ground clearance | E42: 181 | F42: MM | G42: SRC_RENAULT_NO_R4_PAGE | H42: MEDIUM | I42: 2026-07-06 | J42: 1.4
A43: TECH_000036 | C43: RENAULT_4_EVOLUTION_URBAN | D43: WLTP range | E43: 308 | F43: KM | G43: SRC_RENAULT_NO_R4_PRICELIST | H43: MEDIUM | I43: 2026-07-06 | J43: 1.4
A44: TECH_000037 | C44: RENAULT_4_EVOLUTION_URBAN | D44: WLTP consumption | E44: 14.7 | F44: KWH_100KM | G44: SRC_RENAULT_NO_R4_PRICELIST | H44: MEDIUM | I44: 2026-07-06 | J44: 1.4
A45: TECH_000038 | C45: RENAULT_4_EVOLUTION_URBAN | D45: DC max charging | E45: 80 | F45: KW | G45: SRC_RENAULT_NO_R4_PRICELIST | H45: MEDIUM | I45: 2026-07-06 | J45: 1.4
A46: TECH_000039 | C46: RENAULT_4_EVOLUTION_URBAN | D46: AC max charging | E46: 11 | F46: KW | G46: SRC_RENAULT_NO_R4_PRICELIST | H46: MEDIUM | I46: 2026-07-06 | J46: 1.4
A47: TECH_000040 | C47: RENAULT_4_EVOLUTION_URBAN | D47: Battery net | E47: 40 | F47: KWH | G47: SRC_RENAULT_NO_R4_PRICELIST | H47: MEDIUM | I47: 2026-07-06 | J47: 1.4
A48: TECH_000041 | C48: RENAULT_4_EVOLUTION_URBAN | D48: Torque | E48: 225 | F48: NM | G48: SRC_RENAULT_NO_R4_PRICELIST | H48: MEDIUM | I48: 2026-07-06 | J48: 1.4
A49: TECH_000042 | C49: RENAULT_4_EVOLUTION_URBAN | D49: Kerb weight | E49: 1492 | F49: KG | G49: SRC_RENAULT_NO_R4_PRICELIST | H49: MEDIUM | I49: 2026-07-06 | J49: 1.4
A50: TECH_000043 | C50: RENAULT_4_EVOLUTION_URBAN | D50: Boot volume | E50: 420 | F50: L | G50: SRC_RENAULT_NO_R4_PAGE | H50: MEDIUM | I50: 2026-07-06 | J50: 1.4
A51: TECH_000044 | C51: RENAULT_4_EVOLUTION_COMFORT | D51: WLTP range | E51: 407 | F51: KM | G51: SRC_RENAULT_NO_R4_PRICELIST | H51: MEDIUM | I51: 2026-07-06 | J51: 1.4
A52: TECH_000045 | C52: RENAULT_4_EVOLUTION_COMFORT | D52: WLTP consumption | E52: 15.2 | F52: KWH_100KM | G52: SRC_RENAULT_NO_R4_PRICELIST | H52: MEDIUM | I52: 2026-07-06 | J52: 1.4
A53: TECH_000046 | C53: RENAULT_4_EVOLUTION_COMFORT | D53: DC max charging | E53: 100 | F53: KW | G53: SRC_RENAULT_NO_R4_PRICELIST | H53: MEDIUM | I53: 2026-07-06 | J53: 1.4
A54: TECH_000047 | C54: RENAULT_4_EVOLUTION_COMFORT | D54: AC max charging | E54: 11 | F54: KW | G54: SRC_RENAULT_NO_R4_PRICELIST | H54: MEDIUM | I54: 2026-07-06 | J54: 1.4
... A83: TECH_000076 | C83: RENAULT_4_ICONIC_PLEIN_SUD | D83: Torque | E83: 245 | F83: NM | G83: SRC_RENAULT_NO_R4_PRICELIST | H83: MEDIUM | I83: 2026-07-06 | J83: 1.4
A84: TECH_000077 | B84: SKODA_ELROQ | D84: Length | E84: 4488 | F84: MM | G84: SRC_SKODA_GLOBAL_TECHDATA | H84: MEDIUM | I84: 2026-07-06 | J84: 1.4
A85: TECH_000078 | B85: SKODA_ELROQ | D85: Width | E85: 1884 | F85: MM | G85: SRC_SKODA_GLOBAL_TECHDATA | H85: MEDIUM | I85: 2026-07-06 | J85: 1.4
...

Sheet 05_Equipment
A1: EquipmentID | B1: ConfigurationID | C1: EquipmentDefinitionID | D1: Availability | E1: SourceID | F1: Confidence
A2: EQ_000001 | B2: RENAULT_4_EVOLUTION_URBAN | C2: EQ_ACC | D2: UNAVAILABLE | E2: SRC_RENAULT_NO_R4_PRICELIST | F2: MEDIUM
A3: EQ_000002 | B3: RENAULT_4_EVOLUTION_COMFORT | C3: EQ_ACC | D3: UNAVAILABLE | E3: SRC_RENAULT_NO_R4_PRICELIST | F3: MEDIUM
A4: EQ_000003 | B4: RENAULT_4_TECHNO | C4: EQ_ACC | D4: STANDARD | E4: SRC_RENAULT_NO_R4_PRICELIST | F4: MEDIUM
A5: EQ_000004 | B5: RENAULT_4_TECHNO_PLEIN_SUD | C5: EQ_ACC | D5: STANDARD | E5: SRC_RENAULT_NO_R4_PRICELIST | F5: MEDIUM
A6: EQ_000005 | B6: RENAULT_4_ICONIC | C6: EQ_ACC | D6: STANDARD | E6: SRC_RENAULT_NO_R4_PRICELIST | F6: MEDIUM
A7: EQ_000006 | B7: RENAULT_4_ICONIC_PLEIN_SUD | C7: EQ_ACC | D7: STANDARD | E7: SRC_RENAULT_NO_R4_PRICELIST | F7: MEDIUM
A8: EQ_000007 | B8: SKODA_ELROQ_ESSENCE_60 | C8: EQ_ACC | D8: STANDARD | E8: SRC_SKODA_NO_ELROQ_PRICELIST | F8: MEDIUM
A9: EQ_000008 | B9: SKODA_ELROQ_SELECTION_60 | C9: EQ_ACC | D9: STANDARD | E9: SRC_SKODA_NO_ELROQ_PRICELIST | F9: MEDIUM
A10: EQ_000009 | B10: SKODA_ELROQ_SELECTION_85X | C10: EQ_ACC | D10: STANDARD | E10: SRC_SKODA_NO_ELROQ_PRICELIST | F10: MEDIUM
A11: EQ_000010 | B11: SKODA_ELROQ_RS | C11: EQ_ACC | D11: STANDARD | E11: SRC_SKODA_NO_ELROQ_PRICELIST | F11: MEDIUM
A12: EQ_000011 | B12: VOLVO_EX30_P8_AWD | C12: EQ_ACC | D12: STANDARD | E12: SRC_MOTORNO_EX30_2024 | F12: MEDIUM
... A53: EQ_000052 | B53: KIA_EV2_FWD_LONG_RANGE_GT_LINE | C53: EQ_APP | D53: STANDARD | E53: SRC_BOS_KIA_EV2_QUOTE | F53: MEDIUM

Sheet 06_EquipmentDefinitions
A1: EquipmentDefinitionID | B1: Category | C1: Name | D1: Description | E1: Weighted | F1: Notes
A2: EQ_ACC | B2: Core tech | C2: Adaptive cruise control | E2: TRUE | F2: Må-krav, men kvalitet scores separat.
A3: EQ_REAR_CAMERA | B3: Core tech | C3: Ryggekamera | E3: TRUE | F3: Minimumskrav for parkering.
A4: EQ_360 | B4: Core tech | C4: 360-kamera | E4: TRUE | F4: Høy praktisk verdi i garasje/parkering.
A5: EQ_CARPLAY | B5: Core tech | C5: Apple CarPlay | E5: TRUE | F5: Viktig mobilintegrasjon.
A6: EQ_OTA | B6: Core tech | C6: OTA-oppdateringer | E6: TRUE | F6: Viktig for teknologisk aldring.
A7: EQ_NAV_CHARGE | B7: Core tech | C7: Ladeplanlegging i navigasjon | E7: TRUE | F7: Vurder kvalitet og integrasjon.
A8: EQ_MATRIX | B8: Safety/comfort | C8: Matrix/adaptive LED | E8: TRUE | F8: Kan gi livskvalitet, særlig vinter/mørke.
A9: EQ_HEATPUMP | B9: Efficiency | C9: Varmepumpe | E9: TRUE | F9: Viktig i nordisk klima.
A10: EQ_LANE_CENTER | B10: Driver assist | C10: Lane centering | E10: TRUE | F10: Kvalitet viktigere enn navn.
A11: EQ_APP | B11: Core tech | C11: Bil-app | E11: TRUE | F11: Forvarming, lading, status.
A12: EQ_DIGITAL_KEY | B12: Convenience | C12: Digital nøkkel | E12: FALSE | F12: Registreres, lav vekt.
A13: EQ_HUD | B13: Convenience | C13: Head-up display | E13: FALSE | F13: Kan være positivt, men ikke sentralt.
... A21: EQ_WIRELESS_CHARGE | B21: Convenience | C21: Trådløs mobillading | E21: FALSE | F21: Avhenger av implementasjon.

Sheet 07_Reviews
A1: ReviewID | B1: VehicleID | C1: ConfigurationID | D1: Category | E1: Score | F1: Confidence | G1: Summary | H1: EvidenceID | I1: FrameworkVersion
A2: REV_000001 | C2: TESLA_MODEL_3_LONG_RANGE_RWD | D2: Kjøreopplevelse | E2: 4 | F2: HIGH | G2: To uavhengige profesjonelle tester (Motor.no, Cars.com) bekrefter betydelig redusert kupestoy i den oppgraderte Model 3-plattformen sammenlignet med tidligere arsmodeller; dekkstoy fremheves som blant de beste i klassen. Testet pa Long Range AWD/Long Range, men deler karosseri og lydisolasjon med Long Range bakhjulsdrift. [Kriterium W001] | H2: EV_000001,EV_000002 | I2: 1.2
A3: REV_000002 | C3: TESLA_MODEL_3_LONG_RANGE_RWD | D3: Kjøreopplevelse | E3: 4 | F3: MEDIUM | G3: Motor.no gir 8/10 for komfort og beskriver fjaeringen som behagelig ved hoyere hastighet; Cars.com bekrefter at det ikke oppstar bra stot takket vaere frekvensavhengige dempere. Testet pa AWD/Long Range-varianter; RWD-spesifikk fjaeringskarakter er ikke uavhengig bekreftet. [Kriterium W002] | H3: EV_000003,EV_000004 | I3: 1.2
A4: REV_000003 | C4: TESLA_MODEL_3_LONG_RANGE_RWD | D4: Kjøreopplevelse | E4: 3 | F4: MEDIUM | G4: Motor.no rapporterer suveren sikt fremover, men darlig sikt bakover - sistnevnte er en reell praktisk ulempe ved manovrering. Kun en uavhengig kilde funnet. [Kriterium W003] | H4: EV_000006 | I4: 1.2
A5: REV_000004 | C5: TESLA_MODEL_3_LONG_RANGE_RWD | D5: Kjøreopplevelse | E5: 4 | F5: MEDIUM | G5: Motor.no beskriver direkte og relativt tung styrefolelse med umiddelbar respons, og gir 10/10 for kjoreegenskaper. Kun en uavhengig kilde funnet. [Kriterium W004] | H5: EV_000005 | I5: 1.2
A6: REV_000005 | C6: TESLA_MODEL_3_LONG_RANGE_RWD | D6: Teknologi | E6: 3 | F6: MEDIUM | G6: Cars.com dokumenterer konkrete brukssvakheter: bereringsbaserte blinklysknapper som til tider ikke reagerte, og at telefonnokkelen av og til ikke registrerte foreren. Skjermavhengig betjening omtales som et bevisst, men diskutabelt designvalg. Kun en uavhengig kilde funnet. [Kriterium W005] | H6: EV_000007 | I6: 1.2
A7: REV_000006 | C7: TESLA_MODEL_3_LONG_RANGE_RWD | D7: Teknologi | E7: 1 | F7: MEDIUM | G7: MacRumors bekrefter at Apple CarPlay per undersokelsestidspunkt (juli 2026) fortsatt ikke stottes pa noen Tesla-modell, inkludert Model 3. Tesla har varslet tradlos CarPlay "i lopet av kommende maneder" (kunngjort november 2025), men uten bekreftet lanseringsdato. [Kriterium W007] | H7: EV_000008 | I7: 1.2
A8: REV_000007 | C8: TESLA_MODEL_3_LONG_RANGE_RWD | D8: Rekkevidde/lading | E8: 4 | F8: MEDIUM | G8: Offisiell spesifikasjon viser 250 kW DC-hurtiglading (opptil 282 km pa 15 minutter) og 13,6 kWh/100km forbruk for denne konfigurasjonen - godt over minimumsbehovet gitt lav estimert arlig kjorelengde (~8000 km/ar), men ladehastighet er uansett lavt vektet i denne kriteriemodellen. [Kriterium W020] | H8: EV_000009,EV_000010 | I8: 1.2
A9: REV_000008 | C9: RENAULT_4_TECHNO | D9: Kjøreopplevelse | E9: 4 | F9: MEDIUM | G9: RAC Drive rapporterer at kupeen er "impressively quiet" med lite vind- og veistoy selv over lange avstander. Kun en uavhengig kilde funnet; Motor.no kommenterte ikke stoyniva eksplisitt. [Kriterium W001] | H9: EV_000011 | I9: 1.4
A10: REV_000009 | C10: RENAULT_4_TECHNO | D10: Kjøreopplevelse | E10: 3 | F10: LOW | G10: Motoriserende funn: Motor.no rapporterer at bilen "tramper urolig rundt pa ujevn vei" med ubehagelig humpete kjoring pa harde skjoter, mens RAC Drive pa samme drivlinje (150 Comfort Range) rapporterer at fjaeringen "smothers potholes and speed bumps quietly." De to profesjonelle kildene motsier hverandre direkte om komfort - dokumentert som uenighet, ikke lost ved a velge en foretrukket verdi (jf. rammeverkets prinsipp om a dokumentere uenighet mellom autoritative kilder). [Kriterium W002] | H10: EV_000012,EV_000013 | I10: 1.4
A11: REV_000010 | C11: RENAULT_4_TECHNO | D11: Kjøreopplevelse | E11: 3 | F11: MEDIUM | G11: Motor.no rapporterer at en 180cm passasjer sa vidt far plass bak en like hoy forer i baksetet, og at pedalplassering er trang - en reell praktisk ulempe. Samtidig gir hoyere sittestilling bedre oversikt over omgivelsene. Blandet funn fra en uavhengig kilde. [Kriterium W003] | H11: EV_000014 | I11: 1.4
A12: REV_000011 | C12: RENAULT_4_TECHNO | D12: Kjøreopplevelse | E12: 4 | F12: MEDIUM | G12: RAC Drive beskriver styringen som "accurate and well weighted, making it easy to place into a corner." Kun en uavhengig kilde funnet. [Kriterium W004] | H12: EV_000015 | I12: 1.4
A13: REV_000012 | C13: RENAULT_4_TECHNO | D13: Teknologi | E13: 4 | F13: MEDIUM | G13: Motor.no beskriver Google-baserte infotainmentsystemet som "blant de bedre," med stemmestyring og ruteplanlegging inkludert automatisk forvarming av batteriet som fungerer "stralende." Kun en uavhengig kilde funnet. [Kriterium W005] | H13: EV_000016 | I13: 1.4
... A41: REV_000040 | C41: KIA_EV2_FWD_LONG_RANGE_GT_LINE | D41: Økonomi | E41: 4 | F41: MEDIUM | G41: Grunnprisen for selve GT Line-trimmen (346 417 kr) er faktisk lavest av alle fem, for nest-best rekkevidde (453 km) og det mest omfattende standardutstyret registrert i dette datasettet. Totalprisen i det spesifikke tilbudet (423 340 kr) reflekterer kjoperens egne tilvalg (4-seter, vinterhjul) og er ikke representativt for trimmens egen verdi. Vurdert pa grunnprisen: sterk verdi for pengene. [Kriterium W017] | H41: EV_000052 | I41: 1.4

Sheet 08_Evidence
A1: EvidenceID | B1: VehicleID | C1: ConfigurationID | D1: Observation | E1: SourceID | F1: Confidence
A2: EV_000001 | B2: TESLA_MODEL_3 | D2: Cabin/road noise (2024+ refresh): Motor.no: tire noise now among the best in class; noise level noticeably lower after the 2024 refresh (tested: Long Range AWD). | E2: SRC_MOTORNO_MODEL3_2024 | F2: HIGH
A3: EV_000002 | B3: TESLA_MODEL_3 | D3: Cabin/road noise (2024+ refresh): Cars.com: NVH reduced a claimed 20% vs. previous generation; thicker padding, insulation and new acoustic glass muffle the interior (tested: Long Range). | E3: SRC_CARSCOM_MODEL3_2024 | F3: HIGH
A4: EV_000003 | B4: TESLA_MODEL_3 | D4: Ride comfort/suspension: Motor.no: stiff at low speed, comfortable at higher speeds; scored 8/10 for comfort (tested: Long Range AWD). | E4: SRC_MOTORNO_MODEL3_2024 | F4: MEDIUM
A5: EV_000004 | B5: TESLA_MODEL_3 | D5: Ride comfort/suspension: Cars.com: frequency-dependent damper valves adapt to impacts; no jarring hits or unsettledness; tire impacts quieter and less intrusive (tested: Long Range). | E5: SRC_CARSCOM_MODEL3_2024 | F5: MEDIUM
A6: EV_000005 | B6: TESLA_MODEL_3 | D6: Steering precision: Motor.no: direct, somewhat heavy steering feel with immediate response to small inputs; awarded 10/10 for driving characteristics (tested: Long Range AWD). | E6: SRC_MOTORNO_MODEL3_2024 | F6: MEDIUM
A7: EV_000006 | B7: TESLA_MODEL_3 | D7: Forward/rear visibility: Motor.no: excellent forward visibility, poor rearward visibility (tested: Long Range AWD). | E7: SRC_MOTORNO_MODEL3_2024 | F7: MEDIUM
A8: EV_000007 | B8: TESLA_MODEL_3 | D8: Infotainment control scheme: Cars.com: touch-capacitive turn-signal controls "didn't engage at all" at times, reviewer "often hit the wrong turn direction"; phone key occasionally failed to recognize presence (tested: Long Range). | E8: SRC_CARSCOM_MODEL3_2024 | F8: MEDIUM
A9: EV_000008 | B9: TESLA_MODEL_3 | D9: Apple CarPlay availability: MacRumors (2025-11-16): CarPlay not currently supported on any Tesla model; Tesla plans standard wireless CarPlay 'in coming months' per Bloomberg's Mark Gurman, appearing as a window within Tesla's interface rather than replacing it. | E9: SRC_MACRUMORS_CARPLAY_2025 | F9: MEDIUM
A10: EV_000009 | C10: TESLA_MODEL_3_LONG_RANGE_RWD | D10: DC fast-charging power: Official Tesla specification: Supercharging-Max rated at 250 kW, adding up to 282 km of range in 15 minutes for the Long Range bakhjulsdrift configuration. | E10: SRC_TESLA_NO_MODEL3_CONFIGURATOR | F10: MEDIUM
A11: EV_000010 | C11: TESLA_MODEL_3_LONG_RANGE_RWD | D11: Real-world energy consumption: Official Tesla specification: rated power consumption of 13.6 kWh/100km for Long Range bakhjulsdrift, CO2 efficiency class A. | E11: SRC_TESLA_NO_MODEL3_CONFIGURATOR | F11: MEDIUM
A12: EV_000011 | B12: RENAULT_4 | D12: Cabin/road noise: RAC Drive: "impressively quiet... little wind or road noise", easy to travel long distances (tested: 150 Comfort Range). | E12: SRC_RAC_R4_2026 | F12: MEDIUM
A13: EV_000012 | B13: RENAULT_4 | D13: Ride comfort/suspension: Motor.no: "Bilen tramper urolig rundt pa ujevn vei, og harde skjoter gir ubehagelig humpete kjoring" - large 18" standard wheels place high demands on the suspension for a relaxed ride (tested: 150 Comfort Range). | E13: SRC_MOTORNO_R4_2025 | F13: LOW
A14: EV_000013 | B14: RENAULT_4 | D14: Ride comfort/suspension: RAC Drive: ride "smooths out with speed", suspension "smothers potholes and speed bumps quietly" - directly contradicts Motor.no's finding on the same 150 Comfort Range powertrain (tested: 150 Comfort Range). | E14: SRC_RAC_R4_2026 | F14: LOW
A15: EV_000014 | B15: RENAULT_4 | D15: Rear-seat space and visibility: Motor.no: a 180cm passenger only just fits behind an equally tall driver in the rear seats; higher seating position improves overview of surroundings, though pedal placement remains tight (tested: 150 Comfort Range). | E15: SRC_MOTORNO_R4_2025 | F15: MEDIUM
A16: EV_000015 | B16: RENAULT_4 | D16: Steering precision: RAC Drive: steering is "accurate and well weighted, making it easy to place into a corner" (tested: 150 Comfort Range). | E16: SRC_RAC_R4_2026 | F16: MEDIUM
A17: EV_000016 | B17: RENAULT_4 | D17: Infotainment/software quality: Motor.no: "Infotainmentsystemet fra Google er blant de bedre" - voice control and route planning with automatic battery preheating "fungerer stralende" (tested: 150 Comfort Range). | E17: SRC_MOTORNO_R4_2025 | F17: MEDIUM
A18: EV_000017 | B18: RENAULT_4 | D18: Apple CarPlay availability: Official Renault Norway specification lists wired/wireless smartphone mirroring with Android Auto and Apple CarPlay as standard; RAC Drive independently confirms "Android Auto and Apple CarPlay smartphone mirroring comes on all models." | E18: SRC_RENAULT_NO_R4_PAGE | F18: HIGH
A19: EV_000018 | C19: RENAULT_4_TECHNO | D19: DC fast-charging power: Official Renault Norway price list: DC fast charging up to 100 kW, 15-80% in approximately 30 minutes, for the 52 kWh Comfort Range battery fitted to Techno. | E19: SRC_RENAULT_NO_R4_PRICELIST | F19: MEDIUM
A20: EV_000019 | C20: RENAULT_4_TECHNO | D20: Real-world energy consumption: Official Renault Norway price list: rated consumption of 155 Wh/km (15.5 kWh/100km) for Techno (52 kWh Comfort Range). | E20: SRC_RENAULT_NO_R4_PRICELIST | F20: MEDIUM
A21: EV_000020 | B21: SKODA_ELROQ | D21: Cabin/road noise: Motor.no: "hjulstoyen - en familiesvakhet for bilene pa MEB-plattformen - som odelegger her"; Elroq had the most wheel noise of five compared cars (tested: Elroq 60 with Motor-pakke). | E21: SRC_MOTORNO_ELROQ_2025 | F21: MEDIUM
A22: EV_000021 | B22: SKODA_ELROQ | D22: Cabin/road noise: What Car?: "fractionally quieter at 70mph than the EV3, S5 and Scenic. Road noise is minimal" - directly contradicts Motor.no's finding on wheel/road noise. | E22: SRC_WHATCAR_ELROQ_2026 | F22: MEDIUM
A23: EV_000022 | B23: SKODA_ELROQ | D23: Ride comfort/suspension: Motor.no: "Fjaeringen er stiv i lavere fart, fast og fin i hoyere fart" (tested: Elroq 60 with Motor-pakke). | E23: SRC_MOTORNO_ELROQ_2025 | F23: MEDIUM
A24: EV_000023 | B24: SKODA_ELROQ | D24: Ride comfort/suspension: What Car?: "standard suspension absorbs imperfections in the road surface extremely well and delivers a controlled ride at all speeds." | E24: SRC_WHATCAR_ELROQ_2026 | F24: MEDIUM
A25: EV_000024 | B25: SKODA_ELROQ | D25: Outward visibility: RAC Drive: good forward visibility overall; "like many rivals the small rear window restricts your rear view a bit." | E25: SRC_RAC_ELROQ_2026 | F25: MEDIUM
A26: EV_000025 | B26: SKODA_ELROQ | D26: Steering precision: What Car?: "steering is well-weighted and precise" with a "helpful tight turning circle." | E26: SRC_WHATCAR_ELROQ_2026 | F26: MEDIUM
A27: EV_000026 | B27: SKODA_ELROQ | D27: Infotainment/software quality: Motor.no: "Betjeningen - ikke minst den pa rattet - er kanskje best av alle," praising a "fin miks av analoge og digitale funksjoner." What Car?: "responds quickly enough and is much easier to operate than... Mini Countryman Electric," though "EV3 and Scenic are even better." | E27: SRC_MOTORNO_ELROQ_2025 | F27: HIGH
A28: EV_000027 | B28: SKODA_ELROQ | D28: Apple CarPlay availability: What Car? confirms "wireless Android Auto and Apple CarPlay smartphone mirroring" on all models; corroborated by official Skoda Norway price list footnote (SmartLink wireless, compatible with Android Auto and Apple CarPlay, standard on all trims). | E28: SRC_WHATCAR_ELROQ_2026 | F28: HIGH
A29: EV_000028 | C29: SKODA_ELROQ_SELECTION_60 | D29: DC fast-charging power: Official Skoda Norway price list: DC fast charging up to 105 kW, 10-80% in approximately 26 minutes, for Selection 60 (58 kWh). | E29: SRC_SKODA_NO_ELROQ_PRICELIST | F29: MEDIUM
A30: EV_000029 | C30: SKODA_ELROQ_SELECTION_60 | D30: Real-world energy consumption: Official Skoda Norway price list: rated consumption of 15,3 kWh/100km for Selection 60. | E30: SRC_SKODA_NO_ELROQ_PRICELIST | F30: MEDIUM
A31: EV_000030 | B31: VOLVO_EX30 | D31: Cabin/road noise: Motor.no: "Lite hjulstoy pa piggfrie vinterdekk" (minimal tire noise on studless winter tires) (tested: P8 AWD). | E31: SRC_MOTORNO_EX30_2024 | F31: MEDIUM
A32: EV_000031 | B32: VOLVO_EX30 | D32: Cabin/road noise: What Car?: "a fairly hushed high-speed cruiser, too, with only a small amount of wind and road noise making its way inside." | E32: SRC_WHATCAR_EX30_2026 | F32: MEDIUM
A33: EV_000032 | B33: VOLVO_EX30 | D33: Ride comfort/suspension: Motor.no: "Svaert stiv over skarpe ujevnheter, men behagelig i fart" (extremely stiff over sharp irregularities, but comfortable at speed) (tested: P8 AWD). | E33: SRC_MOTORNO_EX30_2024 | F33: MEDIUM
A34: EV_000033 | B34: VOLVO_EX30 | D34: Ride comfort/suspension: What Car?: "the balance Volvo has managed to strike between ride comfort and handling is almost spot-on... suspension is supple enough to take the sting out of" common bumps and potholes. | E34: SRC_WHATCAR_EX30_2026 | F34: MEDIUM
A35: EV_000034 | B35: VOLVO_EX30 | D35: Outward visibility: What Car?: "not as easy to see out of as a Kona Electric, #1 or #3, with the windscreen pillars blocking some of your view at junctions and roundabouts." | E35: SRC_WHATCAR_EX30_2026 | F35: MEDIUM
A36: EV_000035 | B36: VOLVO_EX30 | D36: Steering precision: What Car?: "reasonably accurate, allowing you to place the nose of the car with confidence, although some drivers might find the steering is a little too light, even in its heaviest mode." Separately, Motor.no criticized physical steering-wheel button ergonomics ("rattbetjeningen... trekker ned"), a distinct control-layout complaint rather than steering feel itself (tested: P8 AWD). | E36: SRC_WHATCAR_EX30_2026 | F36: MEDIUM
A37: EV_000036 | B37: VOLVO_EX30 | D37: Infotainment/software quality: Motor.no: Google-based system "fungerer bra" (works well), though driver-assistance features were "lunefull pa norske vinterveier" (temperamental on Norwegian winter roads) - adjusting adaptive cruise speed/interval "viste seg i praksis umulig" (proved practically impossible). What Car?: the Google-based system is "fundamentally excellent," responsive, most functions easy to find. | E37: SRC_MOTORNO_EX30_2024 | F37: HIGH
A38: EV_000037 | B38: VOLVO_EX30 | D38: Apple CarPlay availability: What Car?: "Wireless Android Auto and Apple CarPlay are also included." | E38: SRC_WHATCAR_EX30_2026 | F38: MEDIUM
A39: EV_000038 | C39: VOLVO_EX30_P8_AWD | D39: DC fast-charging power: Official Volvo Norway specification: DC fast charging up to 175 kW, 10-80% in approximately 27 minutes, for P8 AWD (69 kWh). | E39: SRC_VOLVO_NO_EX30_SPECS | F39: MEDIUM
A40: EV_000039 | C40: VOLVO_EX30_P8_AWD | D40: Real-world energy consumption: Official Volvo Norway specification: rated consumption of 17.5 kWh/100km (WLTP combined) for P8 AWD. | E40: SRC_VOLVO_NO_EX30_SPECS | F40: MEDIUM
...

Sheet 09_Sources
A1: SourceID | B1: Type | C1: Title | D1: Publisher | E1: URL | F1: PublishedDate | G1: RetrievedDate | H1: Notes
A2: SRC_TESLA_NO_MODEL3_CONFIGURATOR | B2: MANUFACTURER | C2: Model 3 – Sportslig elektrisk sedan | D2: Tesla | E2: https://www.tesla.com/no_no/model3 | G2: 2026-07-06 | H2: Official Tesla Norway configurator/specification page. Technical values retrieved by switching between the Model 3 (RWD), Premium (Long Range AWD / Long Range RWD) and Performance trim tabs on the live page.
A3: SRC_MOTORNO_MODEL3_2024 | B3: PROFESSIONAL_REVIEW | C3: Motor har testet nye Tesla Model 3 | D3: Motor.no | E3: https://www.motor.no/bil/motor-har-testet-nye-tesla-model-3/262378 | G3: 2026-07-06 | H3: Test av Tesla Model 3 Long Range firehjulsdrift (AWD). Dekker kupestoy, komfort, styring og sikt.
A4: SRC_CARSCOM_MODEL3_2024 | B4: PROFESSIONAL_REVIEW | C4: 2024 Tesla Model 3 Review: My, How You've Improved | D4: Cars.com | E4: https://www.cars.com/articles/2024-tesla-model-3-review-my-how-youve-improved-483077/ | F4: 2024 | G4: 2026-07-06 | H4: Test av Tesla Model 3 Long Range. Dekker NVH/stoydemping, fjaering og infotainment-betjening.
A5: SRC_MACRUMORS_CARPLAY_2025 | B5: PROFESSIONAL_REVIEW | C5: Heres When Tesla is Expected to Add Support for Apple CarPlay | D5: MacRumors | E5: https://www.macrumors.com/2025/11/16/tesla-carplay-support-in-coming-months/ | F5: 2025-11-16 | G5: 2026-07-06 | H5: Rapporterer status og planer for Apple CarPlay-stotte pa Tesla-kjoretoy, inkludert Model 3.
A6: SRC_RENAULT_NO_R4_PAGE | B6: MANUFACTURER | C6: Renault 4 E-Tech electric | Renault.no | D6: Renault (RN Nordic AB NUF) | E6: https://www.renault.no/personbil/renault-4-e-tech-electric | G6: 2026-07-06 | H6: Official Renault Norway product page. Dimensions, boot volume (evolution default view), ground clearance, driver-assistance feature list, CarPlay/Android Auto support.
A7: SRC_RENAULT_NO_R4_PRICELIST | B7: MANUFACTURER | C7: Prisliste Renault 4 E-Tech Electric (Versjon 2, 01-06-2026) | D7: Renault (RN Nordic AB NUF) | E7: https://rn-nordic-prod.objects.frb.io/Cars/Personbil/Renault-4-E-Tech-electric/PDF/Prisliste-Renault-4-Plein-Sud-01.06.26-2.pdf | F7: 2026-06-01 | G7: 2026-07-06 | H7: Official Norwegian price list PDF. Per-trim WLTP range, consumption, motor power, torque, DC/AC charging, kerb weight, payload, pricing, and full equipment/feature comparison including adaptive cruise control availability by trim.
A8: SRC_MOTORNO_R4_2025 | B8: PROFESSIONAL_REVIEW | C8: Motor har prøvekjørt Renault 4 E-Tech | D8: Motor.no | E8: https://www.motor.no/bil/motor-har-provekjort-renault-4-e-tech/316619 | G8: 2026-07-06 | H8: Test av Renault 4 E-Tech 150 Comfort Range (52 kWh, 150 hk). Dekker fjaering/komfort, sikt og infotainment.
A9: SRC_RAC_R4_2026 | B9: PROFESSIONAL_REVIEW | C9: Renault 4 E-Tech Review 2026: Prices, specs and verdict | D9: RAC Drive | E9: https://www.rac.co.uk/drive/car-reviews/renault/4-e-tech/4-e-tech/ | G9: 2026-07-06 | H9: UK professional review. Covers steering, cabin/road noise, ride comfort, and confirms Apple CarPlay/Android Auto support on all models.
A10: SRC_SKODA_NO_ELROQ_PAGE | B10: MANUFACTURER | C10: Škoda Elroq | Ny kompakt el-SUV med god plass | D10: Škoda (Harald A. Møller AS) | E10: https://www.skoda-auto.no/modeller/elroq/elroq | G10: 2026-07-06 | H10: Official Skoda Norway product page. General range/boot/pricing highlights and feature descriptions.
A11: SRC_SKODA_NO_ELROQ_PRICELIST | B11: MANUFACTURER | C11: Prisliste Škoda Elroq 2027-modell | D11: Škoda (Harald A. Møller AS) | E11: https://www.skoda-auto.no/_doc/293e338b-26f2-4601-9123-356e20a88ca5 | F11: 2026-06-29 | G11: 2026-07-06 | H11: Official Norwegian price list, 2027 model year, dated 29.06.2026. Per-trim range, consumption, system power, DC charge time, pricing, and full equipment comparison including adaptive cruise control and rearview camera standard on all trims.
A12: SRC_SKODA_GLOBAL_TECHDATA | B12: MANUFACTURER | C12: Elroq Technical specifications (Skoda Storyboard) | D12: Škoda Auto a.s. | E12: https://cdn.skoda-storyboard.com/2025/04/Skoda_Elroq_Technical_data_28ca6795.pdf | F12: 2025-05-05 | G12: 2026-07-06 | H12: Official global technical data sheet (5.5.2025 revision). Used only for physical dimensions (length, width, height, wheelbase, ground clearance, boot volume) not covered by the Norway 2027 price list. Note: this sheet predates the Norway 2027-model price list by roughly a model year; power/battery/range figures in this sheet do not match the Norway 2027 price list exactly (e.g. Elroq 60: 150kW/59kWh global vs 140kW/58kWh NO 2027) - a documented cross-source discrepancy, likely a running spec revision between model years. Norway price list figures are used for all range/power/battery/charging facts; this sheet is used only for dimensions.
A13: SRC_MOTORNO_ELROQ_2025 | B13: PROFESSIONAL_REVIEW | C13: Motor har testet Skoda Elroq | D13: Motor.no | E13: https://www.motor.no/bil/motor-har-testet-skoda-elroq/316871 | G13: 2026-07-06 | H13: Test av Skoda Elroq 60 med Motor-pakke. Dekker kupestoy (hjulstoy), fjaering, og betjening/infotainment.
A14: SRC_WHATCAR_ELROQ_2026 | B14: PROFESSIONAL_REVIEW | C14: Skoda Elroq Review 2026, Price & Specs | D14: What Car? | E14: https://www.whatcar.com/skoda/elroq/estate/review/n27301 | G14: 2026-07-06 | H14: UK professional review. Covers CarPlay/infotainment, steering, ride comfort and cabin noise.
A15: SRC_RAC_ELROQ_2026 | B15: PROFESSIONAL_REVIEW | C15: Skoda Elroq Review 2026: Prices, specs and verdict | D15: RAC Drive | E15: https://www.rac.co.uk/drive/car-reviews/skoda/elroq/elroq/ | G15: 2026-07-06 | H15: UK professional review. Covers outward visibility and driving position.
A16: SRC_VOLVO_NO_EX30_SPECS | B16: MANUFACTURER | C16: Volvo EX30 helelektrisk SUV | Spesifikasjoner | D16: Volvo Car Norway AS | E16: https://www.volvocars.com/no/cars/ex30-electric/specifications/ | G16: 2026-07-06 | H16: Official Volvo Norway specifications page. Per-configuration (P5, P5 Long Range, P8 AWD) power, torque, range, consumption, battery, charging, weights, plus full vehicle dimensions.
A17: SRC_MOTORNO_EX30_2024 | B17: PROFESSIONAL_REVIEW | C17: Motor har testet Volvo EX30 | D17: Motor.no | E17: https://www.motor.no/bil/motor-har-testet-volvo-ex30/267416 | G17: 2026-07-06 | H17: Test av Volvo EX30 P8 AWD (64 kWh, 428 hk). Dekker kupestoy, fjaering, rattbetjening, infotainment, og forerassistenter pa norske vinterveier.
A18: SRC_WHATCAR_EX30_2026 | B18: PROFESSIONAL_REVIEW | C18: Volvo EX30 Review 2026, Price & Specs | D18: What Car? | E18: https://www.whatcar.com/volvo/ex30/estate/review/n26262 | G18: 2026-07-06 | H18: UK professional review. Covers CarPlay, steering, ride comfort, cabin noise, and outward visibility.
A19: SRC_BOS_KIA_EV2_QUOTE | B19: MANUFACTURER | C19: Tilbud: Kia EV2 FWD Long Range GT Line | D19: Bertel O. Steen Lorenskog (authorized Kia dealer) | F19: 2026-07-06 | G19: 2026-07-06 | H19: Official dealer sales quote (PDF), valid to 2026-07-12. Covers configuration, trim/equipment list, and full pricing breakdown for the specific GT Line configuration. No battery/range/charging/dimension figures included. Customer contact details in the source document deliberately excluded from this citation.
A20: SRC_KIA_NETTBUTIKK_EV2 | B20: MANUFACTURER | C20: EV2 FWD Long Range GT Line - Oppsummering (Kia nettbutikk) | D20: Kia Norge | E20: https://nettbutikk.kia.no/ev2/oppsummering | G20: 2026-07-06 | H20: Official Kia Norway configurator, saved configuration code A2231F29 (verified directly by fetching the live page 2026-07-06 - matches text supplied by user exactly). Technical data section contains confirmed unit-label errors on Kia's own page template: "Bagasjerom"/"Frunk" labeled kg (should be L, volume), "Forbruk" labeled kWh/km (should be kWh/100km - confirmed by cross-check: 62kWh battery / 15.2kWh-per-100km implies ~408km range, consistent with the stated 453km WLTP figure; taken literally as kWh/km the range would be ~4km, which is physically absurd), "Batterikapasitet" labeled kW (should be kWh, energy not power - same cross-check applies). Numeric values are trusted (official source, tied to a specific saved configuration); unit labels corrected based on physical plausibility and internal arithmetic consistency, not assumed.
A21: SRC_MOTORNO_EV2_2026 | B21: PROFESSIONAL_REVIEW | C21: Prøvekjørt: Kia EV2, nå begynner smått å bli virkelig godt | D21: Motor.no | E21: https://www.motor.no/aktuelt/provekjort-kia-ev2-na-begynner-smatt-a-bli-virkelig-godt/350785 | G21: 2026-07-06 | H21: Test av Kia EV2 Standard Range (42.2 kWh, 147 hk), testet i Lisboa. Dekker fjaering/komfort og sikt.
A22: SRC_WHATCAR_EV2_2026 | B22: PROFESSIONAL_REVIEW | C22: Kia EV2 Review 2026, Price & Specs | D22: What Car? | E22: https://www.whatcar.com/kia/ev2/hatchback/review/n28833 | G22: 2026-07-06 | H22: UK professional review. Covers CarPlay, steering, ride comfort, cabin noise and outward visibility.
A23: SRC_RAC_EV2_2026 | B23: PROFESSIONAL_REVIEW | C23: Kia EV2 Review 2026: Prices, specs and verdict | D23: RAC Drive | E23: https://www.rac.co.uk/drive/car-reviews/kia/ev2/ev2/ | G23: 2026-07-06 | H23: UK professional review. Covers infotainment/touchscreen quality.
A24: SRC_ELBIL_VOLVO_EX30_WINTER | B24: PROFESSIONAL_REVIEW | C24: Vintertest av Volvo EX30: Denne bilen forteller deg om batterihelsen sin | D24: Norsk elbilforening (elbil.no) | E24: https://elbil.no/vinter-test-av-volvo-ex30-denne-bilen-forteller-deg-om-batterihelsen-sin/ | F24: 2025-02-26 | G24: 2026-07-06 | H24: Independent winter test (Tier A: independent winter testing). Tested Twin Performance (dual-motor AWD Ultra) - matches VOLVO_EX30_P8_AWD powertrain. Estimated ~75% of WLTP range retained under real winter conditions (down to approx. -20C) after accounting for a mid-route fast-charge stop.
A25: SRC_ELBIL_RENAULT4_TEST | B25: PROFESSIONAL_REVIEW | C25: Test av Renault 4: Billig sjarmklump som fort blir dyr | D25: Norsk elbilforening (elbil.no) | E25: https://elbil.no/test-av-renault-4/ | F25: 2025-11-05 | G25: 2026-07-06 | H25: General road test, not a dedicated winter cold-chamber test. Tested Iconic trim (52kWh, same powertrain as Techno, different equipment level) at highway consumption of 1.81 kWh/mil (18.1 kWh/100km) at constant 100km/h in 5-7C conditions - not extreme winter cold. Measured range at this consumption: 287km. Used as a cautious proxy only, explicitly flagged as trim- and condition-mismatched to the Techno configuration and to true deep-winter conditions.
A26: SRC_TESLA_NO_MODEL3_DESIGN | B26: MANUFACTURER | C26: Design din Model 3 | Tesla | D26: Tesla | E26: https://www.tesla.com/no_no/model3/design | G26: 2026-07-06 | H26: Official Tesla Norway configurator. Verified total price for Long Range bakhjulsdrift (Long Range RWD) with no optional extras selected: 369990 kr excl. VAT/fees, 400539 kr incl. VAT and fees.

Sheet 10_Scoring
A1: ScoreID | B1: ConfigurationID | C1: CriterionID | D1: ReviewID | E1: FrameworkVersion | F1: RawScore | G1: WeightedScore | H1: Explanation
A2: SCORE_000001 | B2: TESLA_MODEL_3_LONG_RANGE_RWD | C2: W001 | D2: REV_000001 | E2: 1.4 | F2: =ROUND(INDEX('07_Reviews'!$E:$E,MATCH(D2,'07_Reviews'!$A:$A,0))/5*100,2) | G2: =ROUND(F2*INDEX('01_Criteria'!$F:$F,MATCH(C2,'01_Criteria'!$A:$A,0))/100,2) | H2: Review score 4/5 (normalized RawScore = 80.0/100 on a documented 1-5 scale, since the framework does not prescribe a numeric scale). WeightedScore = RawScore x Weight(8)/100 = 6.4. Traceable to REV_000001 -> supporting Evidence -> cited Source.
A3: SCORE_000002 | B3: TESLA_MODEL_3_LONG_RANGE_RWD | C3: W002 | D3: REV_000002 | E3: 1.4 | F3: =ROUND(INDEX('07_Reviews'!$E:$E,MATCH(D3,'07_Reviews'!$A:$A,0))/5*100,2) | G3: =ROUND(F3*INDEX('01_Criteria'!$F:$F,MATCH(C3,'01_Criteria'!$A:$A,0))/100,2) | H3: Review score 4/5 (normalized RawScore = 80.0/100 on a documented 1-5 scale, since the framework does not prescribe a numeric scale). WeightedScore = RawScore x Weight(7)/100 = 5.6. Traceable to REV_000002 -> supporting Evidence -> cited Source.
A4: SCORE_000003 | B4: TESLA_MODEL_3_LONG_RANGE_RWD | C4: W003 | D4: REV_000003 | E4: 1.4 | F4: =ROUND(INDEX('07_Reviews'!$E:$E,MATCH(D4,'07_Reviews'!$A:$A,0))/5*100,2) | G4: =ROUND(F4*INDEX('01_Criteria'!$F:$F,MATCH(C4,'01_Criteria'!$A:$A,0))/100,2) | H4: Review score 3/5 (normalized RawScore = 60.0/100 on a documented 1-5 scale, since the framework does not prescribe a numeric scale). WeightedScore = RawScore x Weight(5)/100 = 3.0. Traceable to REV_000003 -> supporting Evidence -> cited Source.
A5: SCORE_000004 | B5: TESLA_MODEL_3_LONG_RANGE_RWD | C5: W004 | D5: REV_000004 | E5: 1.4 | F5: =ROUND(INDEX('07_Reviews'!$E:$E,MATCH(D5,'07_Reviews'!$A:$A,0))/5*100,2) | G5: =ROUND(F5*INDEX('01_Criteria'!$F:$F,MATCH(C5,'01_Criteria'!$A:$A,0))/100,2) | H5: Review score 4/5 (normalized RawScore = 80.0/100 on a documented 1-5 scale, since the framework does not prescribe a numeric scale). WeightedScore = RawScore x Weight(5)/100 = 4.0. Traceable to REV_000004 -> supporting Evidence -> cited Source.
A6: SCORE_000005 | B6: TESLA_MODEL_3_LONG_RANGE_RWD | C6: W005 | D6: REV_000005 | E6: 1.4 | F6: =ROUND(INDEX('07_Reviews'!$E:$E,MATCH(D6,'07_Reviews'!$A:$A,0))/5*100,2) | G6: =ROUND(F6*INDEX('01_Criteria'!$F:$F,MATCH(C6,'01_Criteria'!$A:$A,0))/100,2) | H6: Review score 3/5 (normalized RawScore = 60.0/100 on a documented 1-5 scale, since the framework does not prescribe a numeric scale). WeightedScore = RawScore x Weight(7)/100 = 4.2. Traceable to REV_000005 -> supporting Evidence -> cited Source.
A7: SCORE_000006 | B7: TESLA_MODEL_3_LONG_RANGE_RWD | C7: W007 | D7: REV_000006 | E7: 1.4 | F7: =ROUND(INDEX('07_Reviews'!$E:$E,MATCH(D7,'07_Reviews'!$A:$A,0))/5*100,2) | G7: =ROUND(F7*INDEX('01_Criteria'!$F:$F,MATCH(C7,'01_Criteria'!$A:$A,0))/100,2) | H7: Review score 1/5 (normalized RawScore = 20.0/100 on a documented 1-5 scale, since the framework does not prescribe a numeric scale). WeightedScore = RawScore x Weight(3)/100 = 0.6. Traceable to REV_000006 -> supporting Evidence -> cited Source.
A8: SCORE_000007 | B8: TESLA_MODEL_3_LONG_RANGE_RWD | C8: W020 | D8: REV_000007 | E8: 1.4 | F8: =ROUND(INDEX('07_Reviews'!$E:$E,MATCH(D8,'07_Reviews'!$A:$A,0))/5*100,2) | G8: =ROUND(F8*INDEX('01_Criteria'!$F:$F,MATCH(C8,'01_Criteria'!$A:$A,0))/100,2) | H8: Review score 4/5 (normalized RawScore = 80.0/100 on a documented 1-5 scale, since the framework does not prescribe a numeric scale). WeightedScore = RawScore x Weight(2)/100 = 1.6. Traceable to REV_000007 -> supporting Evidence -> cited Source.
A9: SCORE_000008 | B9: RENAULT_4_TECHNO | C9: W001 | D9: REV_000008 | E9: 1.4 | F9: =ROUND(INDEX('07_Reviews'!$E:$E,MATCH(D9,'07_Reviews'!$A:$A,0))/5*100,2) | G9: =ROUND(F9*INDEX('01_Criteria'!$F:$F,MATCH(C9,'01_Criteria'!$A:$A,0))/100,2) | H9: Traceable to REV_000008 -> supporting Evidence -> cited Source. RawScore/WeightedScore computed via the ADR-005 formula engine.
A10: SCORE_000009 | B10: RENAULT_4_TECHNO | C10: W002 | D10: REV_000009 | E10: 1.4 | F10: =ROUND(INDEX('07_Reviews'!$E:$E,MATCH(D10,'07_Reviews'!$A:$A,0))/5*100,2) | G10: =ROUND(F10*INDEX('01_Criteria'!$F:$F,MATCH(C10,'01_Criteria'!$A:$A,0))/100,2) | H10: Traceable to REV_000009 -> supporting Evidence -> cited Source. RawScore/WeightedScore computed via the ADR-005 formula engine.
A11: SCORE_000010 | B11: RENAULT_4_TECHNO | C11: W003 | D11: REV_000010 | E11: 1.4 | F11: =ROUND(INDEX('07_Reviews'!$E:$E,MATCH(D11,'07_Reviews'!$A:$A,0))/5*100,2) | G11: =ROUND(F11*INDEX('01_Criteria'!$F:$F,MATCH(C11,'01_Criteria'!$A:$A,0))/100,2) | H11: Traceable to REV_000010 -> supporting Evidence -> cited Source. RawScore/WeightedScore computed via the ADR-005 formula engine.
A12: SCORE_000011 | B12: RENAULT_4_TECHNO | C12: W004 | D12: REV_000011 | E12: 1.4 | F12: =ROUND(INDEX('07_Reviews'!$E:$E,MATCH(D12,'07_Reviews'!$A:$A,0))/5*100,2) | G12: =ROUND(F12*INDEX('01_Criteria'!$F:$F,MATCH(C12,'01_Criteria'!$A:$A,0))/100,2) | H12: Traceable to REV_000011 -> supporting Evidence -> cited Source. RawScore/WeightedScore computed via the ADR-005 formula engine.
A13: SCORE_000012 | B13: RENAULT_4_TECHNO | C13: W005 | D13: REV_000012 | E13: 1.4 | F13: =ROUND(INDEX('07_Reviews'!$E:$E,MATCH(D13,'07_Reviews'!$A:$A,0))/5*100,2) | G13: =ROUND(F13*INDEX('01_Criteria'!$F:$F,MATCH(C13,'01_Criteria'!$A:$A,0))/100,2) | H13: Traceable to REV_000012 -> supporting Evidence -> cited Source. RawScore/WeightedScore computed via the ADR-005 formula engine.
... A41: SCORE_000041 | B41: KIA_EV2_FWD_LONG_RANGE_GT_LINE | C41: W017 | D41: REV_000040 | E41: 1.4 | F41: =ROUND(INDEX('07_Reviews'!$E:$E,MATCH(D41,'07_Reviews'!$A:$A,0))/5*100,2) | G41: =ROUND(F41*INDEX('01_Criteria'!$F:$F,MATCH(C41,'01_Criteria'!$A:$A,0))/100,2) | H41: Traceable to REV_000040 -> supporting Evidence -> cited Source. RawScore/WeightedScore computed via the ADR-005 formula engine.

Sheet 11_DecisionLog
A1: DecisionID | B1: Date | C1: FrameworkVersion | D1: Change | E1: Reason | F1: DecisionOwner | G1: Notes
B2: 2026-07-04 | C2: 0.2 | D2: Initial analysis-system workbook structure | E2: Built robust template with criteria, equipment definitions, evidence and scoring tabs | F2: Bjørn/ChatGPT
A3: DEC_ISSUE_001 | B3: 2026-07-06 | C3: 1.0 | D3: Synchronized workbook structure with Framework Version 1.0 | E3: Issue #1 workbook schema sync | F3: Codex
A4: DEC_IMPL_002 | B4: 2026-07-06 | C4: 1.2 | D4: Implemented Configuration Status (ADR-004 / IMPL-002) | E4: Closed the gap between the documented Configuration Status enumeration and the workbook schema; added Status column to 03_Configurations | F4: Claude | G4: Populated existing Tesla Model 3 configurations as AVAILABLE, backed by the Tesla Norway configurator source already cited in their Notes.
A5: DEC_GAP_E_001 | B5: 2026-07-06 | C5: 1.2 | D5: Reconciled Garasje category in docs/02_criteria-and-weighting.md | E5: The vertical-slice review found 01_Criteria already contains a live, weighted "Garasje" category (W019, weight 3) that docs/02 did not document as its own category - only as a sub-example under Practicality. Documentation-only fix; no weights or 01_Criteria data changed. | F5: Claude | G5: Gap E from the post-vertical-slice architecture review. No ADR required (descriptive reconciliation of already-live data, not a methodology change).
